2022-03-18 14:58:48,811 INFO: WebApp startup [in C:\Led-Lights\webApp\app\__init__.py:45]
2022-03-22 14:29:18,911 INFO: WebApp startup [in C:\Led-Lights\webApp\app\__init__.py:45]
2022-03-22 14:32:21,742 INFO: WebApp startup [in C:\Led-Lights\webApp\app\__init__.py:45]
2022-03-22 14:33:29,694 INFO: WebApp startup [in C:\Led-Lights\webApp\app\__init__.py:45]
2022-03-22 14:35:48,788 INFO: WebApp startup [in C:\Led-Lights\webApp\app\__init__.py:45]
2022-03-22 14:51:34,268 INFO: WebApp startup [in C:\Led-Lights\webApp\app\__init__.py:45]
2022-03-22 14:53:03,960 INFO: WebApp startup [in C:\Led-Lights\webApp\app\__init__.py:45]
2022-03-22 14:55:50,217 INFO: WebApp startup [in C:\Led-Lights\webApp\app\__init__.py:45]
2022-03-22 14:57:27,006 INFO: WebApp startup [in C:\Led-Lights\webApp\app\__init__.py:45]
2022-03-22 14:59:40,792 INFO: WebApp startup [in C:\Led-Lights\webApp\app\__init__.py:45]
2022-03-24 14:31:17,341 INFO: WebApp startup [in C:\Led-Lights\webApp\app\__init__.py:45]
2022-03-24 14:31:26,138 ERROR: Exception on /addscene [GET] [in c:\led-lights\webapp\venv\lib\site-packages\flask\app.py:1892]
Traceback (most recent call last):
  File "c:\led-lights\webapp\venv\lib\site-packages\flask\app.py", line 2447, in wsgi_app
    response = self.full_dispatch_request()
  File "c:\led-lights\webapp\venv\lib\site-packages\flask\app.py", line 1952, in full_dispatch_request
    rv = self.handle_user_exception(e)
  File "c:\led-lights\webapp\venv\lib\site-packages\flask\app.py", line 1821, in handle_user_exception
    reraise(exc_type, exc_value, tb)
  File "c:\led-lights\webapp\venv\lib\site-packages\flask\_compat.py", line 39, in reraise
    raise value
  File "c:\led-lights\webapp\venv\lib\site-packages\flask\app.py", line 1950, in full_dispatch_request
    rv = self.dispatch_request()
  File "c:\led-lights\webapp\venv\lib\site-packages\flask\app.py", line 1936, in dispatch_request
    return self.view_functions[rule.endpoint](**req.view_args)
  File "c:\led-lights\webapp\venv\lib\site-packages\flask_login\utils.py", line 272, in decorated_view
    return func(*args, **kwargs)
  File "C:\Led-Lights\webApp\app\routes.py", line 361, in addscene
    if scene.id > maxid:
AttributeError: 'dict' object has no attribute 'id'
2022-03-24 14:32:54,439 INFO: WebApp startup [in C:\Led-Lights\webApp\app\__init__.py:45]
2022-03-24 14:32:57,718 ERROR: Exception on /addscene [GET] [in c:\led-lights\webapp\venv\lib\site-packages\flask\app.py:1892]
Traceback (most recent call last):
  File "c:\led-lights\webapp\venv\lib\site-packages\flask\app.py", line 2447, in wsgi_app
    response = self.full_dispatch_request()
  File "c:\led-lights\webapp\venv\lib\site-packages\flask\app.py", line 1952, in full_dispatch_request
    rv = self.handle_user_exception(e)
  File "c:\led-lights\webapp\venv\lib\site-packages\flask\app.py", line 1821, in handle_user_exception
    reraise(exc_type, exc_value, tb)
  File "c:\led-lights\webapp\venv\lib\site-packages\flask\_compat.py", line 39, in reraise
    raise value
  File "c:\led-lights\webapp\venv\lib\site-packages\flask\app.py", line 1950, in full_dispatch_request
    rv = self.dispatch_request()
  File "c:\led-lights\webapp\venv\lib\site-packages\flask\app.py", line 1936, in dispatch_request
    return self.view_functions[rule.endpoint](**req.view_args)
  File "c:\led-lights\webapp\venv\lib\site-packages\flask_login\utils.py", line 272, in decorated_view
    return func(*args, **kwargs)
  File "C:\Led-Lights\webApp\app\routes.py", line 361, in addscene
    if scene[int(id)] > maxid:
UnboundLocalError: local variable 'id' referenced before assignment
2022-03-24 14:33:46,673 INFO: WebApp startup [in C:\Led-Lights\webApp\app\__init__.py:45]
2022-03-24 14:33:50,221 ERROR: Exception on /addscene [GET] [in c:\led-lights\webapp\venv\lib\site-packages\flask\app.py:1892]
Traceback (most recent call last):
  File "c:\led-lights\webapp\venv\lib\site-packages\flask\app.py", line 2447, in wsgi_app
    response = self.full_dispatch_request()
  File "c:\led-lights\webapp\venv\lib\site-packages\flask\app.py", line 1952, in full_dispatch_request
    rv = self.handle_user_exception(e)
  File "c:\led-lights\webapp\venv\lib\site-packages\flask\app.py", line 1821, in handle_user_exception
    reraise(exc_type, exc_value, tb)
  File "c:\led-lights\webapp\venv\lib\site-packages\flask\_compat.py", line 39, in reraise
    raise value
  File "c:\led-lights\webapp\venv\lib\site-packages\flask\app.py", line 1950, in full_dispatch_request
    rv = self.dispatch_request()
  File "c:\led-lights\webapp\venv\lib\site-packages\flask\app.py", line 1936, in dispatch_request
    return self.view_functions[rule.endpoint](**req.view_args)
  File "c:\led-lights\webapp\venv\lib\site-packages\flask_login\utils.py", line 272, in decorated_view
    return func(*args, **kwargs)
  File "C:\Led-Lights\webApp\app\routes.py", line 361, in addscene
    if scene[int(id)] > maxid:
TypeError: int() argument must be a string, a bytes-like object or a number, not 'builtin_function_or_method'
2022-03-24 14:34:31,737 INFO: WebApp startup [in C:\Led-Lights\webApp\app\__init__.py:45]
2022-03-24 14:34:33,808 ERROR: Exception on /addscene [GET] [in c:\led-lights\webapp\venv\lib\site-packages\flask\app.py:1892]
Traceback (most recent call last):
  File "c:\led-lights\webapp\venv\lib\site-packages\flask\app.py", line 2447, in wsgi_app
    response = self.full_dispatch_request()
  File "c:\led-lights\webapp\venv\lib\site-packages\flask\app.py", line 1952, in full_dispatch_request
    rv = self.handle_user_exception(e)
  File "c:\led-lights\webapp\venv\lib\site-packages\flask\app.py", line 1821, in handle_user_exception
    reraise(exc_type, exc_value, tb)
  File "c:\led-lights\webapp\venv\lib\site-packages\flask\_compat.py", line 39, in reraise
    raise value
  File "c:\led-lights\webapp\venv\lib\site-packages\flask\app.py", line 1950, in full_dispatch_request
    rv = self.dispatch_request()
  File "c:\led-lights\webapp\venv\lib\site-packages\flask\app.py", line 1936, in dispatch_request
    return self.view_functions[rule.endpoint](**req.view_args)
  File "c:\led-lights\webapp\venv\lib\site-packages\flask_login\utils.py", line 272, in decorated_view
    return func(*args, **kwargs)
  File "C:\Led-Lights\webApp\app\routes.py", line 361, in addscene
    if scene[int(id)] > maxid:
TypeError: int() argument must be a string, a bytes-like object or a number, not 'builtin_function_or_method'
2022-03-24 14:35:34,845 INFO: WebApp startup [in C:\Led-Lights\webApp\app\__init__.py:45]
2022-03-24 14:36:14,960 INFO: WebApp startup [in C:\Led-Lights\webApp\app\__init__.py:45]
2022-03-24 14:38:58,994 INFO: WebApp startup [in C:\Led-Lights\webApp\app\__init__.py:45]
2022-03-25 14:23:02,063 INFO: WebApp startup [in C:\Led-Lights\webApp\app\__init__.py:45]
2022-03-25 14:46:17,324 INFO: WebApp startup [in C:\Led-Lights\webApp\app\__init__.py:45]
2022-03-25 14:47:55,326 ERROR: Exception on /index [GET] [in c:\led-lights\webapp\venv\lib\site-packages\flask\app.py:1892]
Traceback (most recent call last):
  File "c:\led-lights\webapp\venv\lib\site-packages\flask\app.py", line 2447, in wsgi_app
    response = self.full_dispatch_request()
  File "c:\led-lights\webapp\venv\lib\site-packages\flask\app.py", line 1952, in full_dispatch_request
    rv = self.handle_user_exception(e)
  File "c:\led-lights\webapp\venv\lib\site-packages\flask\app.py", line 1821, in handle_user_exception
    reraise(exc_type, exc_value, tb)
  File "c:\led-lights\webapp\venv\lib\site-packages\flask\_compat.py", line 39, in reraise
    raise value
  File "c:\led-lights\webapp\venv\lib\site-packages\flask\app.py", line 1950, in full_dispatch_request
    rv = self.dispatch_request()
  File "c:\led-lights\webapp\venv\lib\site-packages\flask\app.py", line 1936, in dispatch_request
    return self.view_functions[rule.endpoint](**req.view_args)
  File "c:\led-lights\webapp\venv\lib\site-packages\flask_login\utils.py", line 272, in decorated_view
    return func(*args, **kwargs)
  File "C:\Led-Lights\webApp\app\routes.py", line 125, in index
    sch_date = datetime.datetime.strptime(i["start_time"], '%Y-%m-%dT%H:%M:%S.%f')
  File "C:\Program Files (x86)\Python37-32\lib\_strptime.py", line 577, in _strptime_datetime
    tt, fraction, gmtoff_fraction = _strptime(data_string, format)
  File "C:\Program Files (x86)\Python37-32\lib\_strptime.py", line 359, in _strptime
    (data_string, format))
ValueError: time data '1900-01-01Tresxest:00.000' does not match format '%Y-%m-%dT%H:%M:%S.%f'
