2022-03-25 14:47:58,846 ERROR: Exception on /index [GET] [in c:\led-lights\webapp\venv\lib\site-packages\flask\app.py:1892]
Traceback (most recent call last):
  File "c:\led-lights\webapp\venv\lib\site-packages\flask\app.py", line 2447, in wsgi_app
    response = self.full_dispatch_request()
  File "c:\led-lights\webapp\venv\lib\site-packages\flask\app.py", line 1952, in full_dispatch_request
    rv = self.handle_user_exception(e)
  File "c:\led-lights\webapp\venv\lib\site-packages\flask\app.py", line 1821, in handle_user_exception
    reraise(exc_type, exc_value, tb)
  File "c:\led-lights\webapp\venv\lib\site-packages\flask\_compat.py", line 39, in reraise
    raise value
  File "c:\led-lights\webapp\venv\lib\site-packages\flask\app.py", line 1950, in full_dispatch_request
    rv = self.dispatch_request()
  File "c:\led-lights\webapp\venv\lib\site-packages\flask\app.py", line 1936, in dispatch_request
    return self.view_functions[rule.endpoint](**req.view_args)
  File "c:\led-lights\webapp\venv\lib\site-packages\flask_login\utils.py", line 272, in decorated_view
    return func(*args, **kwargs)
  File "C:\Led-Lights\webApp\app\routes.py", line 125, in index
    sch_date = datetime.datetime.strptime(i["start_time"], '%Y-%m-%dT%H:%M:%S.%f')
  File "C:\Program Files (x86)\Python37-32\lib\_strptime.py", line 577, in _strptime_datetime
    tt, fraction, gmtoff_fraction = _strptime(data_string, format)
  File "C:\Program Files (x86)\Python37-32\lib\_strptime.py", line 359, in _strptime
    (data_string, format))
ValueError: time data '1900-01-01Tresxest:00.000' does not match format '%Y-%m-%dT%H:%M:%S.%f'
2022-03-25 14:48:00,238 ERROR: Exception on /index [GET] [in c:\led-lights\webapp\venv\lib\site-packages\flask\app.py:1892]
Traceback (most recent call last):
  File "c:\led-lights\webapp\venv\lib\site-packages\flask\app.py", line 2447, in wsgi_app
    response = self.full_dispatch_request()
  File "c:\led-lights\webapp\venv\lib\site-packages\flask\app.py", line 1952, in full_dispatch_request
    rv = self.handle_user_exception(e)
  File "c:\led-lights\webapp\venv\lib\site-packages\flask\app.py", line 1821, in handle_user_exception
    reraise(exc_type, exc_value, tb)
  File "c:\led-lights\webapp\venv\lib\site-packages\flask\_compat.py", line 39, in reraise
    raise value
  File "c:\led-lights\webapp\venv\lib\site-packages\flask\app.py", line 1950, in full_dispatch_request
    rv = self.dispatch_request()
  File "c:\led-lights\webapp\venv\lib\site-packages\flask\app.py", line 1936, in dispatch_request
    return self.view_functions[rule.endpoint](**req.view_args)
  File "c:\led-lights\webapp\venv\lib\site-packages\flask_login\utils.py", line 272, in decorated_view
    return func(*args, **kwargs)
  File "C:\Led-Lights\webApp\app\routes.py", line 125, in index
    sch_date = datetime.datetime.strptime(i["start_time"], '%Y-%m-%dT%H:%M:%S.%f')
  File "C:\Program Files (x86)\Python37-32\lib\_strptime.py", line 577, in _strptime_datetime
    tt, fraction, gmtoff_fraction = _strptime(data_string, format)
  File "C:\Program Files (x86)\Python37-32\lib\_strptime.py", line 359, in _strptime
    (data_string, format))
ValueError: time data '1900-01-01Tresxest:00.000' does not match format '%Y-%m-%dT%H:%M:%S.%f'
2022-03-25 14:48:20,980 INFO: WebApp startup [in C:\Led-Lights\webApp\app\__init__.py:45]
2022-04-05 14:28:30,801 INFO: WebApp startup [in C:\Led-Lights\webApp\app\__init__.py:45]
2022-04-11 14:38:42,401 INFO: WebApp startup [in C:\Led-Lights\webApp\app\__init__.py:45]
2022-04-11 14:46:14,678 INFO: WebApp startup [in C:\Led-Lights\webApp\app\__init__.py:45]
2022-04-11 14:49:28,728 ERROR: Exception on /editschedule/141 [GET] [in c:\led-lights\webapp\venv\lib\site-packages\flask\app.py:1892]
Traceback (most recent call last):
  File "c:\led-lights\webapp\venv\lib\site-packages\flask\app.py", line 2447, in wsgi_app
    response = self.full_dispatch_request()
  File "c:\led-lights\webapp\venv\lib\site-packages\flask\app.py", line 1952, in full_dispatch_request
    rv = self.handle_user_exception(e)
  File "c:\led-lights\webapp\venv\lib\site-packages\flask\app.py", line 1821, in handle_user_exception
    reraise(exc_type, exc_value, tb)
  File "c:\led-lights\webapp\venv\lib\site-packages\flask\_compat.py", line 39, in reraise
    raise value
  File "c:\led-lights\webapp\venv\lib\site-packages\flask\app.py", line 1950, in full_dispatch_request
    rv = self.dispatch_request()
  File "c:\led-lights\webapp\venv\lib\site-packages\flask\app.py", line 1936, in dispatch_request
    return self.view_functions[rule.endpoint](**req.view_args)
  File "c:\led-lights\webapp\venv\lib\site-packages\flask_login\utils.py", line 272, in decorated_view
    return func(*args, **kwargs)
  File "C:\Led-Lights\webApp\app\routes.py", line 333, in editschedule
    currentScene = dataDict[int(id)-1]
IndexError: list index out of range
2022-04-11 14:53:55,988 INFO: WebApp startup [in C:\Led-Lights\webApp\app\__init__.py:45]
2022-04-11 14:53:59,028 ERROR: Exception on /editschedule/141 [GET] [in c:\led-lights\webapp\venv\lib\site-packages\flask\app.py:1892]
Traceback (most recent call last):
  File "c:\led-lights\webapp\venv\lib\site-packages\flask\app.py", line 2447, in wsgi_app
    response = self.full_dispatch_request()
  File "c:\led-lights\webapp\venv\lib\site-packages\flask\app.py", line 1952, in full_dispatch_request
    rv = self.handle_user_exception(e)
  File "c:\led-lights\webapp\venv\lib\site-packages\flask\app.py", line 1821, in handle_user_exception
    reraise(exc_type, exc_value, tb)
  File "c:\led-lights\webapp\venv\lib\site-packages\flask\_compat.py", line 39, in reraise
    raise value
  File "c:\led-lights\webapp\venv\lib\site-packages\flask\app.py", line 1950, in full_dispatch_request
    rv = self.dispatch_request()
  File "c:\led-lights\webapp\venv\lib\site-packages\flask\app.py", line 1936, in dispatch_request
    return self.view_functions[rule.endpoint](**req.view_args)
  File "c:\led-lights\webapp\venv\lib\site-packages\flask_login\utils.py", line 272, in decorated_view
    return func(*args, **kwargs)
  File "C:\Led-Lights\webApp\app\routes.py", line 338, in editschedule
    sch_date = datetime.datetime.strptime(currentScene["start_time"], '%Y-%m-%dT%H:%M:%S.%f')
UnboundLocalError: local variable 'currentScene' referenced before assignment
2022-04-11 14:57:06,492 INFO: WebApp startup [in C:\Led-Lights\webApp\app\__init__.py:45]
2022-04-11 14:59:11,127 ERROR: Exception on /index [GET] [in c:\led-lights\webapp\venv\lib\site-packages\flask\app.py:1892]
Traceback (most recent call last):
  File "c:\led-lights\webapp\venv\lib\site-packages\flask\app.py", line 2447, in wsgi_app
    response = self.full_dispatch_request()
  File "c:\led-lights\webapp\venv\lib\site-packages\flask\app.py", line 1952, in full_dispatch_request
    rv = self.handle_user_exception(e)
  File "c:\led-lights\webapp\venv\lib\site-packages\flask\app.py", line 1821, in handle_user_exception
    reraise(exc_type, exc_value, tb)
  File "c:\led-lights\webapp\venv\lib\site-packages\flask\_compat.py", line 39, in reraise
    raise value
  File "c:\led-lights\webapp\venv\lib\site-packages\flask\app.py", line 1950, in full_dispatch_request
    rv = self.dispatch_request()
  File "c:\led-lights\webapp\venv\lib\site-packages\flask\app.py", line 1936, in dispatch_request
    return self.view_functions[rule.endpoint](**req.view_args)
  File "c:\led-lights\webapp\venv\lib\site-packages\flask_login\utils.py", line 272, in decorated_view
    return func(*args, **kwargs)
  File "C:\Led-Lights\webApp\app\routes.py", line 125, in index
    sch_date = datetime.datetime.strptime(i["start_time"], '%Y-%m-%dT%H:%M:%S.%f')
  File "C:\Program Files (x86)\Python37-32\lib\_strptime.py", line 577, in _strptime_datetime
    tt, fraction, gmtoff_fraction = _strptime(data_string, format)
  File "C:\Program Files (x86)\Python37-32\lib\_strptime.py", line 359, in _strptime
    (data_string, format))
ValueError: time data '1900-01-01T8:00pm:00.000' does not match format '%Y-%m-%dT%H:%M:%S.%f'
2022-04-11 14:59:17,231 ERROR: Exception on /index [GET] [in c:\led-lights\webapp\venv\lib\site-packages\flask\app.py:1892]
Traceback (most recent call last):
  File "c:\led-lights\webapp\venv\lib\site-packages\flask\app.py", line 2447, in wsgi_app
    response = self.full_dispatch_request()
  File "c:\led-lights\webapp\venv\lib\site-packages\flask\app.py", line 1952, in full_dispatch_request
    rv = self.handle_user_exception(e)
  File "c:\led-lights\webapp\venv\lib\site-packages\flask\app.py", line 1821, in handle_user_exception
    reraise(exc_type, exc_value, tb)
  File "c:\led-lights\webapp\venv\lib\site-packages\flask\_compat.py", line 39, in reraise
    raise value
  File "c:\led-lights\webapp\venv\lib\site-packages\flask\app.py", line 1950, in full_dispatch_request
    rv = self.dispatch_request()
  File "c:\led-lights\webapp\venv\lib\site-packages\flask\app.py", line 1936, in dispatch_request
    return self.view_functions[rule.endpoint](**req.view_args)
  File "c:\led-lights\webapp\venv\lib\site-packages\flask_login\utils.py", line 272, in decorated_view
    return func(*args, **kwargs)
  File "C:\Led-Lights\webApp\app\routes.py", line 125, in index
    sch_date = datetime.datetime.strptime(i["start_time"], '%Y-%m-%dT%H:%M:%S.%f')
  File "C:\Program Files (x86)\Python37-32\lib\_strptime.py", line 577, in _strptime_datetime
    tt, fraction, gmtoff_fraction = _strptime(data_string, format)
  File "C:\Program Files (x86)\Python37-32\lib\_strptime.py", line 359, in _strptime
    (data_string, format))
ValueError: time data '1900-01-01T8:00pm:00.000' does not match format '%Y-%m-%dT%H:%M:%S.%f'
2022-04-11 15:00:20,904 INFO: WebApp startup [in C:\Led-Lights\webApp\app\__init__.py:45]
